第五章

![image](img/.jpg)

异常处理

在许多编程书籍中，异常处理在书的后面有一章。然而，在这本书里，由于一些原因，它靠近前面。

第一个原因是异常处理在。因此在 C#代码中非常常见。可以不使用异常处理来编写 C++代码，但这不是 C#的选项。

第二个原因是它允许代码示例更好。如果异常处理是在本书的后面介绍的，早期的代码示例不能使用它，这意味着不能使用良好的编程实践来编写示例。

返回代码有什么问题？

大多数程序员可能都写过类似这样的代码:

```cs
bool success = CallFunction();
if (!success)
{
    // process the error
}
```

这样做没问题，但是必须检查每个返回值是否有错误。如果上面写的是

```cs
CallFunction();
```

任何返回的错误都将被丢弃。虫子就是这么来的。

沟通状态有许多不同的模式；一些函数可能会返回一个`HRESULT`，一些函数可能会返回一个布尔值，而其他函数可能会使用一些其他的机制。

在。NET 运行时世界中，异常是处理错误条件的基本方法。异常比返回代码更好，因为它们不能被忽视。换句话说，就是。NET world 默认是正确的；所有异常都是可见的。

![image](img/.jpg) **注意**在实践中，这意味着你写的任何异常代码都会给你机会搞砸“默认正确”的行为。因此，您在编写异常处理代码时应该特别小心，更重要的是，尽量少写。

尝试和捕捉

为了处理异常，代码需要以稍微不同的方式组织。可能抛出异常的代码段被放在`try`块中，而在`try`块中处理异常的代码被放在`catch`块中。这里有一个例子:

```cs
using System;
class Test
{
    static int Zero = 0;
    public static void Main()
    {
            // watch for exceptions here
       try
       {
            int j = 22 / Zero;
       }
            // exceptions that occur in try are transferred here
       catch (Exception e)
       {
            Console.WriteLine("Exception " + e.Message);
       }
       Console.WriteLine("After catch");
    }
}
```

`try`块包含了一个将产生异常的表达式。在这种情况下，它将生成一个名为`DivideByZeroException`的异常。当分裂发生时。NET 运行时停止执行代码，并搜索发生异常的代码周围的`try`块。然后它寻找一个`catch`块并写出异常消息。

所有 C#异常都继承自一个名为`Exception`的类。例如，`ArgumentException`类继承自`SystemException`类，后者继承自`Exception`。

选择捕捉块

当异常发生时，使用以下方法确定匹配的`catch`块:

1.  运行时搜索包含导致异常的代码的`try`块。如果在当前方法中没有找到`try`块，它将搜索该方法的调用方。
2.  在找到一个`try`块后，它检查`catch`块，看看抛出的异常类型是否可以转换成`catch`语句中列出的异常类型。如果可以进行转换，则该`catch`块是匹配的。
3.  如果找到匹配的`catch`块，则执行该块中的代码。
4.  如果没有一个`catch`块匹配，搜索继续步骤 1。

回到这个例子:

```cs
using System;
class Test
{
    static int Zero = 0;
    public static void Main()
    {
       try
       {
            int j = 22 / Zero;
       }
            // catch a specific exception
       catch (DivideByZeroException e)
       {
            Console.WriteLine("DivideByZero {0}", e);
       }
            // catch any remaining exceptions
       catch (Exception e)
       {
            Console.WriteLine("Exception {0}", e);
       }
    }
}
```

捕捉到`DivideByZeroException`的`catch`块是第一个匹配，因此是被执行的块。`Catch`区块总是必须从最具体到最不具体列出，所以在这个例子中，两个区块不能颠倒。 [<sup>1</sup>](#Fn1)

这个例子有点复杂:

```cs
using System;
class Test
{
    static int Zero = 0;
    static void AFunction()
    {
       int j = 22 / Zero;
            // the following line is never executed.
       Console.WriteLine("In AFunction()");
    }
    public static void Main()
    {
       try
       {
            AFunction();
       }
       catch (DivideByZeroException e)
       {
            Console.WriteLine("DivideByZero {0}", e);
       }
    }
}
```

这里发生了什么？

当执行除法时，会生成一个异常。运行时开始在`AFunction()`中搜索一个`try`块，但是没有找到，所以它跳出`AFunction()`并在`Main()`中检查一个`try`块。它找到一个，然后寻找匹配的`catch`块。然后执行`catch`块。

有时候，不会有任何`catch`子句匹配。

```cs
using System;
class Test
{
    static int Zero = 0;
    static void AFunction()
    {
       try
       {
            int j = 22 / Zero;
       }
            // this exception doesn't match
       catch (ArgumentOutOfRangeException e)
       {
            Console.WriteLine("OutOfRangeException: {0}", e);
       }
       Console.WriteLine("In AFunction()");
    }
    public static void Main()
    {
       try
       {
            AFunction();
       }
            // this exception doesn't match
       catch (ArgumentException e)
       {
            Console.WriteLine("ArgumentException {0}", e);
       }
    }
}
```

`AFunction()`中的`catch`块和`Main()`中的`catch`块都不匹配抛出的异常。当这种情况发生时，异常被“最后一次机会”异常处理程序捕获。此处理程序采取的操作取决于运行时的配置方式，但它可能会在程序退出前写出异常信息。[2<sup>2</sup>T7】](#Fn2)

将异常传递给调用方

有时候，当一个方法中出现异常时，我们无能为力；它必须由调用函数来处理。有三种基本的方法来处理这个问题，根据它们在调用者中的结果来命名:调用者小心、调用者迷惑和调用者通知。

来电者当心

第一种方法是不捕捉异常。这通常是正确的设计决策，但它可能会使对象处于不正确的状态，如果调用者稍后试图使用它，就会导致问题。它也可能给呼叫者提供不充分的信息来确切地知道发生了什么。

来电者搞不清

第二种方法是捕获异常，进行一些清理，然后重新抛出异常:

```cs
using System;
public class Summer
{
    int m_sum = 0;
    int m_count = 0;
    float m_average;
    public void DoAverage()
    {
       try
       {
            m_average = m_sum / m_count;
       }
       catch (DivideByZeroException e)
       {
            // do some cleanup here
            throw; //rethrow the exception
       }
    }
}
class Test
{
    public static void Main()
    {
       Summer summer = new Summer();
       try
       {
            summer.DoAverage();
       }
       catch (Exception e)
       {
            Console.WriteLine("Exception {0}", e);
       }
    }
}
```

这通常是处理异常的最低标准；异常发生后，对象应该始终保持有效状态。

这被称为调用者混淆，因为当对象在异常发生后处于有效状态时，调用者通常没有什么信息可以继续。在这种情况下，异常信息表明`DivideByZeroException`发生在被调用函数中的某个地方，但没有给出任何关于异常细节或如何修复它的信息。

如果异常中的信息足以让调用者理解发生了什么，这是首选行为。

来电通知

在呼叫者通知中，为用户返回附加信息。被捕获的异常被包装在一个具有附加信息的异常中。

```cs
using System;
public class Summer
{
    int m_sum = 0;
    int m_count = 0;
    float m_average;
    public void DoAverage()
    {
       try
       {
            m_average = m_sum / m_count;
       }
       catch (DivideByZeroException e)
       {
                // wrap exception in another one,
                // adding additional context.
                throw (new DivideByZeroException(
                   "Count is zero in DoAverage()", e));
       }
    }
}
public class Test
{
    public static void Main()
    {
       Summer summer = new Summer();
       try
       {
            summer.DoAverage();
       }
       catch (Exception e)
       {
            Console.WriteLine("Exception: {0}", e);
       }
    }
}
```

当`DivideByZeroException`在`DoAverage()`函数中被捕获时，它被包装在一个新的异常中，为用户提供关于异常原因的附加信息。通常包装异常与被捕获异常的类型相同，但是这可能会根据呈现给调用者的模型而改变。

该程序生成以下输出:

```cs
Exception: System.DivideByZeroException: Count is zero in DoAverage()
  ---> System.DivideByZeroException
   at Summer.DoAverage()
   at Test.Main()
```

如果包装一个异常可以为用户提供有用的信息，这通常是一个好主意。然而，包装是一把双刃剑；如果做错了，事情会变得更糟。有关如何有效包装的更多信息，请参见本章后面的“设计指南”一节。

用户定义的异常类

上一个例子的一个缺点是调用者不能通过查看异常的类型来判断在调用`DoAverage()`时发生了什么异常。要知道异常是因为计数为零而导致的，必须使用字符串`Count is zero`来搜索表达式消息。

这将是非常糟糕的，因为用户将无法相信该文本在该类的后续版本中将保持不变，并且该类的编写者将无法更改该文本。在这种情况下，可以创建一个新的异常类:

```cs
using System;
public class CountIsZeroException: Exception
{
    public CountIsZeroException()
    {
    }
    public CountIsZeroException(string message)
    : base(message)
    {
    }
    public CountIsZeroException(string message, Exception inner)
    : base(message, inner)
    {
    }
}
public class Summer
{
    int m_sum = 0;
    int m_count = 0;
    float m_average;
    public void DoAverage()
    {
       if (m_count == 0)
       {
            throw(new CountIsZeroException("Zero count in DoAverage()"));
       }
       else
       {
            m_average = m_sum / m_count;
       }
    }
}
class Test
{
    public static void Main()
    {
       Summer summer = new Summer();
       try
       {
            summer.DoAverage();
       }
       catch (CountIsZeroException e)
       {
            Console.WriteLine("CountIsZeroException: {0}", e);
       }
    }
}
```

`DoAverage()`现在确定是否会有异常(是否`count`是零)，如果是，创建一个`CountIsZeroException`并抛出它。

在这个例子中，`exception`类有三个构造函数，这是推荐的设计模式。遵循这种设计模式很重要，因为如果缺少接受内部异常的构造函数，就不可能用相同的异常类型包装该异常；它只能用更普通的东西来包装。在上面的例子中，如果我们的调用者没有那个构造函数，被捕获的`CountIsZeroException`就不能被包装在相同类型的异常中，调用者必须在不捕获异常和将其包装在不太特定的类型中做出选择。

在…的早期。NET 中，建议所有用户定义的异常都从`ApplicationException`类派生，但是现在建议简单地使用`Exception`作为基础。[T33](#Fn3)

最后

有时候，在编写函数时，会有一些清理工作需要在函数完成之前完成，比如关闭一个文件。如果发生异常，可以跳过清理。以下代码处理一个文件:

```cs
using System;
using System.IO;
class Processor
{
    int m_count;
    int m_sum;
    public int m_average;
    void CalculateAverage(int countAdd, int sumAdd)
    {
       m_count += countAdd;
       m_sum += sumAdd;
       m_average = m_sum / m_count;
    }
    public void ProcessFile()
    {
       FileStream f = new FileStream("data.txt", FileMode.Open);
       try
       {
            StreamReader t = new StreamReader(f);
            string line;
            while ((line = t.ReadLine()) ! = null)
            {
                int count;
                int sum;
                count = Convert.ToInt32(line);
                line = t.ReadLine();
                sum = Convert.ToInt32(line);
                CalculateAverage(count, sum);
            }
       }
            // always executed before function exit, even if an
            // exception was thrown in the try.
       finally
       {
            f.Close();
       }
    }
}
class Test
{
    public static void Main()
    {
       Processor processor = new Processor();
       try
       {
            processor.ProcessFile();
       }
       catch (Exception e)
       {
            Console.WriteLine("Exception: {0}", e);
       }
    }
}
```

这个例子遍历一个文件，从文件中读取一个`count`和`sum`，并累加一个平均值。然而，如果从文件中读取的第一个`count`是零，会发生什么呢？

如果发生这种情况，`CalculateAverage()`中的除法将抛出一个`DivideByZeroException`，这将中断文件读取循环。如果程序员在编写函数时没有考虑异常，那么对`file.Close()`的调用就会被跳过，文件就会保持打开状态。

无论是否有异常，保证在函数退出之前执行`finally`块中的代码。通过在`finally`块中放置`file.Close()`调用，文件将总是被关闭。

前一个例子中的代码有点笨拙。第 7 章涵盖了`using`语句，该语句通常用于简化资源清理。

顶级异常处理程序

如果我们的程序遇到一个异常，并且没有代码来捕捉这个异常，那么这个异常就会从我们的代码中传递出去，我们依赖于代码调用方的行为。对于控制台应用程序。NET 运行时会将异常的详细信息写出到控制台窗口，但对于其他应用程序类型(ASP。NET、WPF 或 Windows 窗体)，我们的程序将停止执行。用户将丢失任何未保存的工作，并且很难找到异常的原因。

可以添加一个顶级异常处理程序来捕获异常，也许允许用户保存他或她的工作， [<sup>4</sup>](#Fn4) ，并使异常细节可用于故障排除。

最简单的顶级处理程序是应用程序的`Main()`方法中的`try` - `catch`:

```cs
static void Main(string[] args)
{
    try
    {
       Run();
    }
    catch (Exception e)
    {
       // log the exception, show a message to the user, etc.
    }
}
```

对于单线程程序来说，这很好，但是许多程序执行的操作并不发生在主线程上。可以为每个例程编写异常处理程序，但是很容易做错，并且其他线程可能希望将异常返回给主程序。

为了简化这一过程。NET 运行库提供了一个中心位置，当发生未处理的异常时，所有线程都将在这里死亡。我们可以编写一次顶级异常处理代码，并将其应用于任何地方:

```cs
static void Main(string[] args)
{
    AppDomain.CurrentDomain.UnhandledException += UnhandledExceptionHandler;
    int i = 1;
    i--;

    int j = 12 / i;
}
static void UnhandledExceptionHandler (object sender, UnhandledExceptionEventArgs e)
{
    Exception exception = (Exception) e.ExceptionObject;

    Console.WriteLine(exception);
    System.Diagnostics.Debugger.Break();
}
```

`Main()`的第一行将事件处理程序`UnhandledExceptionHandler`连接到当前应用程序域上的`UnhandledException`事件。 [<sup>5</sup>](#Fn5) 每当有未被捕获的异常，处理程序就会被调用。

处理程序将消息写出到控制台窗口(在实际代码中可能不是最好的做法，尤其是没有控制台窗口的代码)，然后，如果附加了调试器，则导致在调试器中执行断点。

效率和开销

在没有垃圾收集的语言中，添加异常处理是很昂贵的，因为函数中的所有对象都必须被跟踪，以确保它们在任何可能抛出异常的时候都被正确销毁。所需的跟踪代码增加了函数的执行时间和代码量。

然而，在 C#中，对象是由垃圾收集器而不是编译器来跟踪的，所以异常处理实现起来非常便宜，并且当异常情况没有发生时，对程序施加的运行时开销很小。然而，当抛出异常时，代价并不小。

设计指南

以下是异常用法的设计指南。

例外就是例外

应使用异常来传达异常情况。不要使用它们来传达预期的事件，比如到达文件的末尾。在类的正常操作中，不应该抛出异常。

![image](img/.jpg) **提示**如果你正在使用 Visual Studio 编写 C#，调试器异常窗口允许你设置调试器在异常抛出时中断。启用此选项是跟踪您的程序是否正在生成任何意外异常的好方法。

相反，不要使用返回值来传递信息，这些信息最好包含在异常中。

选择正确的异常进行换行

包装异常时做出正确的选择非常重要。考虑以下代码:

```cs
try
{
    libraryDataValue.Process();
}
catch (Exception e)
{
    if (e.InnerException is FileNotFoundException)
    {
       Recover(); // Do appropriate recovery
    }
}
```

看一下代码，看看你是否能发现这个错误。问题不在于编写的代码；它和丢失的代码在一起。正确的代码应该是这样的:

```cs
try
{
    libraryDataValue.Process();
}
catch (Exception e)
{
    if (e.InnerException is FileNotFoundException)
    {
       Recover(); // Do appropriate recovery
    }
    else
    {
       throw;
    }
}
```

缺少`else`子句意味着任何抛出的没有类型`FileNotFoundException`的内部异常的异常都将被吞掉，使程序处于意外状态。在这种情况下，我们编写了一些代码，打破了“默认情况下正确”的行为。

然而，这并不是我们的错。错误在于`Process()`方法的作者，他采用了一个非常有用且特定的异常——`FileNotFoundException`——并将其包装在非常通用的`Exception`类型中，迫使我们挖掘内部代码以找出真正发生了什么。这尤其令人讨厌，因为`FileNotFoundException`是一个非常好的异常，不需要包装在另一个类型中。

考虑包装异常时，请考虑以下准则:

*   *评估附加信息的有用程度*。如果异常没有被包装，开发人员会得到什么信息，这就足够了吗？您团队中的其他开发人员是否会使用这些代码来访问源代码(因此他们可以调试代码)，或者它是否是其他人使用的 API，在这种情况下包装可能更有用？
*   *确定何时可能抛出该异常*。如果是在“开发人员犯了一个错误”类中，包装可能就没那么有用了。如果是运行时错误，可能会更有用。
*   *以抛出异常相同粒度级别包装异常*。内部异常中的信息有助于调试，任何人都不必编写依赖于它的代码。
*   *将异常封装在同一类型中，但在消息中包含更多信息通常是一个不错的选择*。

例外情况应尽可能具体

如果您的代码需要抛出异常，它抛出的异常应该有尽可能具体的类型。仅仅定义一个`SupportLibraryException`类并在多个地方使用它是非常诱人的，但是这使得调用者更有可能必须查看该类内部，他们甚至可能在异常消息文本上使用文本匹配来获得期望的行为。花额外的时间，给他们不同的例外情况。然而，如果您想从`SupportLibraryException`中派生出所有特定的异常，那么调用者就可以轻松地编写通用代码。

重试逻辑

前一段时间，我遇到了一个在底层有重试逻辑的系统；如果遇到问题，它会重试十次，每次重试之间会有几秒钟的等待时间。如果重试逻辑失败，它将放弃并抛出异常。然后，同样实现了重试逻辑的调用者将遵循相同的方法，调用者的调用者也是如此。

当系统找到一个丢失的文件时，它不断尝试，直到大约 15 分钟后，它最终向调用者返回一个异常。

重试逻辑有时是不可避免的，但是在你写它之前，花点时间想想是否有更好的方法来组织你的程序。如果您真的编写了它，也要为自己写一个注释，以便将来重新访问代码，确保重试逻辑仍然有用，并且按照您期望的方式运行。

再抛

如包装异常指南中所述，重新抛出它捕获的异常的代码通常是出错的迹象。如果您确实需要重新抛出，请确保执行以下操作:

```cs
throw;
```

而不是这个:

```cs
throw e;
```

第二个选项将丢弃最初与异常一起生成的堆栈跟踪，因此异常看起来像是在重新抛出时产生的。

只有在你有有用的事情要做的时候才抓住

正如本章开头所提到的，编写异常处理代码是一个机会，可以把一个运行良好的系统变成一个运行不正常的系统。我遇到过三种有用的定义 [<sup>6</sup>](#Fn6) :

*   你正在调用一个方法，它有一个众所周知的异常情况，而且，最重要的是，你可以做些什么来从那个情况中恢复过来。典型的例子是你从一个用户那里得到一个文件名，但由于某种原因它不合适(不存在，格式错误，无法打开，等等)。).在这种情况下，重试是要求用户输入另一个文件名。在这种情况下，“某物”意味着“不同的东西”重试几乎从来都不是正确的做法。 [<sup>7</sup>](#Fn7)
*   如果你没有捕捉到异常，程序将会死亡，并且没有其他人在你之上。此时，除了将异常信息捕获到文件或事件日志中，或者告诉用户程序需要退出之外，您什么也做不了，但是这些都是很重要的事情。
*   *你正处于捕捉和包装为你的呼叫者提供真正好处的阶段*。在这种情况下，您将捕获异常，包装它，然后抛出包装的异常。

[<sup>1</sup>](#_Fn1) 更具体地说，捕获派生异常的子句不能列在捕获基本异常的子句之后。

[<sup>2</sup>](#_Fn2) 这种行为可以被应用程序改变。

[<sup>3</sup>](#_Fn3) 如果你正在创建一个库，最好定义一个`UnicornLibraryException`类，然后从那个类派生出你所有的特定类。

[<sup>4</sup>](#_Fn4) 保存他们的工作可能会有问题，因为异常可能会使他们的工作处于无效状态。如果有，拯救它可能是一件坏事。如果你决定保存他们的作品，我建议保存为副本。

[<sup>5</sup>](#_Fn5) 其中引用了两个新概念。关于事件的更多信息，请参见第 23 章[。应用程序域可以被认为是代码执行的整体环境。](23.html)

[<sup>6</sup>](#_Fn6) 有可能是我遗漏了其他病例。在你断定你想做的事情实际上是有用的之前，要非常深思熟虑和深思熟虑。

[<sup>7</sup>](#_Fn7) 假设你正在编写一个手机应用程序，它需要在失去网络访问时具有弹性。如果您编写逻辑来不断尝试网络操作，它可能会工作，除了如果您使用轮询，您会很快耗尽电池。这里的要点是，正确的重试行为通常是您需要在架构上设计的，而不是在底层处理。